Namespace(root_path='kits19/data', list_dir='./lists_kits19', dataset='KiTS19', num_classes=3, max_iterations=50000, max_epochs=150, batch_size=1, n_gpu=1, deterministic=1, base_lr=0.01, img_size=224, seed=1234, n_skip=3, vit_name='R50-ViT-B_16', vit_patches_size=16, checkpoint_dir='./checkpoints_kits19', exp='TU_KiTS19_224')
No checkpoint or best model found. Starting training from scratch.
73500 iterations per epoch. 50000 total iterations.
  0%|                                       | 0/50000 [00:00<?, ?it/s]
Iteration 1: Loss 0.9399
Iteration 2: Loss 0.8905
Iteration 3: Loss 0.8144
Iteration 4: Loss 0.7198
Iteration 5: Loss 0.6272
Iteration 6: Loss 0.5504
Iteration 7: Loss 0.4948
Iteration 8: Loss 0.4518
Iteration 9: Loss 0.4205
Iteration 10: Loss 0.3984
Iteration 11: Loss 0.4263
Iteration 12: Loss 0.3719
Iteration 13: Loss 0.3869
Iteration 14: Loss 0.3573
Iteration 15: Loss 0.4206
Iteration 16: Loss 0.3659
Iteration 17: Loss 0.3481
Iteration 18: Loss 0.3465
Iteration 19: Loss 0.3655
Iteration 20: Loss 0.4101
Iteration 21: Loss 0.3914
Iteration 22: Loss 0.3683
Iteration 23: Loss 0.4021
Iteration 24: Loss 0.3426
Iteration 25: Loss 0.3421
Iteration 26: Loss 0.3423
Iteration 27: Loss 0.3419
Iteration 28: Loss 0.3413
Iteration 29: Loss 0.3409
Iteration 30: Loss 0.3385
Iteration 31: Loss 0.3389
Iteration 32: Loss 0.3386
Iteration 33: Loss 0.3699
Iteration 34: Loss 0.3366
Iteration 35: Loss 0.5226
Iteration 36: Loss 0.3365
Iteration 37: Loss 0.3369
Iteration 38: Loss 0.3372
Iteration 39: Loss 0.3999
Iteration 40: Loss 0.4254
Iteration 41: Loss 0.3369
Iteration 42: Loss 0.3376
Iteration 43: Loss 0.3379
Iteration 44: Loss 0.3378
Iteration 45: Loss 0.4462
Iteration 46: Loss 0.5767
Iteration 47: Loss 0.3947
Iteration 48: Loss 0.3392
Iteration 49: Loss 0.3387
  0%|                                       | 0/50000 [00:55<?, ?it/s]
Traceback (most recent call last):
  File "/home/hous/Desktop/Kidney_Segmentation/TransUNet/train.py", line 82, in <module>
    trainer_kits19(args, net)
  File "/home/hous/Desktop/Kidney_Segmentation/TransUNet/trainer.py", line 145, in trainer_kits19
    val_loss, val_dice = validate(val_loader, model, ce_loss, dice_loss, num_classes)
  File "/home/hous/Desktop/Kidney_Segmentation/TransUNet/trainer.py", line 24, in validate
    for sampled_batch in val_loader:
  File "/home/hous/anaconda3/envs/torch/lib/python3.10/site-packages/torch/utils/data/dataloader.py", line 630, in __next__
    data = self._next_data()
  File "/home/hous/anaconda3/envs/torch/lib/python3.10/site-packages/torch/utils/data/dataloader.py", line 1345, in _next_data
    return self._process_data(data)
  File "/home/hous/anaconda3/envs/torch/lib/python3.10/site-packages/torch/utils/data/dataloader.py", line 1371, in _process_data
    data.reraise()
  File "/home/hous/anaconda3/envs/torch/lib/python3.10/site-packages/torch/_utils.py", line 694, in reraise
    raise exception
ValueError: Caught ValueError in DataLoader worker process 0.
Original Traceback (most recent call last):
  File "/home/hous/anaconda3/envs/torch/lib/python3.10/site-packages/torch/utils/data/_utils/worker.py", line 308, in _worker_loop
    data = fetcher.fetch(index)
  File "/home/hous/anaconda3/envs/torch/lib/python3.10/site-packages/torch/utils/data/_utils/fetch.py", line 51, in fetch
    data = [self.dataset[idx] for idx in possibly_batched_index]
  File "/home/hous/anaconda3/envs/torch/lib/python3.10/site-packages/torch/utils/data/_utils/fetch.py", line 51, in <listcomp>
    data = [self.dataset[idx] for idx in possibly_batched_index]
  File "/home/hous/Desktop/Kidney_Segmentation/TransUNet/datasets/dataset_kits19_list.py", line 46, in __getitem__
    case, slice_idx = self.slices[idx]
ValueError: not enough values to unpack (expected 2, got 0)